<?xml version="1.0" ?>
<robot name="Rice" xmlns:xacro="http://www.ros.org/wiki/xacro">

<xacro:macro name="Rice" params="prefix load_meta:=true">

<xacro:if value="${load_meta}">
  <xacro:include filename="$(find Rice_description)/urdf/materials.xacro" />
  <xacro:include filename="$(find Rice_description)/urdf/Rice.trans" />
  <xacro:include filename="$(find Rice_description)/urdf/Rice.gazebo" />
</xacro:if>

<link name="${prefix}base_link"/>

<link name="${prefix}leg_br">
  <inertial>
    <origin xyz="0.02067495895251803 -0.42960566115027676 -0.059489197402857075" rpy="0 0 0"/>
    <mass value="19.428196282242897"/>
    <inertia ixx="0.69198" iyy="0.118365" izz="0.64895" ixy="-0.001759" iyz="0.04479" ixz="0.016967"/>
  </inertial>
  <visual>
    <origin xyz="0 0 0" rpy="0 0 0"/>
    <geometry>
      <mesh filename="package://Rice_description/meshes/leg_br.stl" scale="0.001 0.001 0.001"/>
    </geometry>
    <material name="Rice_silver"/>
  </visual>
  <collision>
    <origin xyz="0 0 0" rpy="0 0 0"/>
    <geometry>
      <mesh filename="package://Rice_description/meshes/leg_br.stl" scale="0.001 0.001 0.001"/>
    </geometry>
  </collision>
</link>

<link name="${prefix}leg_bl">
  <inertial>
    <origin xyz="-0.020209424216131984 -0.4348060760743736 -0.05818411411396296" rpy="0 0 0"/>
    <mass value="19.9033372562808"/>
    <inertia ixx="0.720932" iyy="0.120784" izz="0.676639" ixy="0.003917" iyz="0.050773" ixz="-0.017565"/>
  </inertial>
  <visual>
    <origin xyz="0 0 0" rpy="0 0 0"/>
    <geometry>
      <mesh filename="package://Rice_description/meshes/leg_bl.stl" scale="0.001 0.001 0.001"/>
    </geometry>
    <material name="Rice_silver"/>
  </visual>
  <collision>
    <origin xyz="0 0 0" rpy="0 0 0"/>
    <geometry>
      <mesh filename="package://Rice_description/meshes/leg_bl.stl" scale="0.001 0.001 0.001"/>
    </geometry>
  </collision>
</link>

<link name="${prefix}leg_fr">
  <inertial>
    <origin xyz="0.020209424438183965 -0.4348060753188833 0.058184114296319" rpy="0 0 0"/>
    <mass value="19.90333719348541"/>
    <inertia ixx="0.720932" iyy="0.120784" izz="0.676639" ixy="-0.003917" iyz="-0.050773" ixz="-0.017565"/>
  </inertial>
  <visual>
    <origin xyz="0 0 0" rpy="0 0 0"/>
    <geometry>
      <mesh filename="package://Rice_description/meshes/leg_fr.stl" scale="0.001 0.001 0.001"/>
    </geometry>
    <material name="Rice_silver"/>
  </visual>
  <collision>
    <origin xyz="0 0 0" rpy="0 0 0"/>
    <geometry>
      <mesh filename="package://Rice_description/meshes/leg_fr.stl" scale="0.001 0.001 0.001"/>
    </geometry>
  </collision>
</link>

<link name="${prefix}leg_fl">
  <inertial>
    <origin xyz="-0.020233756052453953 -0.43473344154932647 0.05820262908150501" rpy="0 0 0"/>
    <mass value="19.897003188386865"/>
    <inertia ixx="0.72058" iyy="0.120724" izz="0.676271" ixy="0.003807" iyz="-0.050689" ixz="0.017537"/>
  </inertial>
  <visual>
    <origin xyz="0 0 0" rpy="0 0 0"/>
    <geometry>
      <mesh filename="package://Rice_description/meshes/leg_fl.stl" scale="0.001 0.001 0.001"/>
    </geometry>
    <material name="Rice_silver"/>
  </visual>
  <collision>
    <origin xyz="0 0 0" rpy="0 0 0"/>
    <geometry>
      <mesh filename="package://Rice_description/meshes/leg_fl.stl" scale="0.001 0.001 0.001"/>
    </geometry>
  </collision>
</link>

<link name="${prefix}wheel_br">
  <inertial>
    <origin xyz="0.7663416407864999 0.46499999999999997 1.0899999999999923" rpy="0 0 0"/>
    <mass value="65.80472593736363"/>
    <inertia ixx="1.584128" iyy="0.836383" izz="0.836383" ixy="0.0" iyz="0.0" ixz="-0.0"/>
  </inertial>
  <visual>
    <origin xyz="0 0 0" rpy="0 0 0"/>
    <geometry>
      <mesh filename="package://Rice_description/meshes/wheel_br.stl" scale="0.001 0.001 0.001"/>
    </geometry>
    <material name="Rice_silver"/>
  </visual>
  <collision>
    <origin xyz="0 0 0" rpy="0 0 0"/>
    <geometry>
      <mesh filename="package://Rice_description/meshes/wheel_br.stl" scale="0.001 0.001 0.001"/>
    </geometry>
  </collision>
</link>

<link name="${prefix}wheel_fr">
  <inertial>
    <origin xyz="0.7663416407865039 0.46499999999999997 1.0372073678943815e-14" rpy="0 0 0"/>
    <mass value="65.80472593736363"/>
    <inertia ixx="1.584128" iyy="0.836383" izz="0.836383" ixy="0.0" iyz="-0.0" ixz="0.0"/>
  </inertial>
  <visual>
    <origin xyz="0 0 0" rpy="0 0 0"/>
    <geometry>
      <mesh filename="package://Rice_description/meshes/wheel_fr.stl" scale="0.001 0.001 0.001"/>
    </geometry>
    <material name="Rice_silver"/>
  </visual>
  <collision>
    <origin xyz="0 0 0" rpy="0 0 0"/>
    <geometry>
      <mesh filename="package://Rice_description/meshes/wheel_fr.stl" scale="0.001 0.001 0.001"/>
    </geometry>
  </collision>
</link>

<link name="${prefix}wheel_bl">
  <inertial>
    <origin xyz="0.0020000000000000018 0.46499999999999997 1.0899999999999923" rpy="0 0 0"/>
    <mass value="65.80472593736363"/>
    <inertia ixx="1.584128" iyy="0.836383" izz="0.836383" ixy="0.0" iyz="0.0" ixz="0.0"/>
  </inertial>
  <visual>
    <origin xyz="0 0 0" rpy="0 0 0"/>
    <geometry>
      <mesh filename="package://Rice_description/meshes/wheel_bl.stl" scale="0.001 0.001 0.001"/>
    </geometry>
    <material name="Rice_silver"/>
  </visual>
  <collision>
    <origin xyz="0 0 0" rpy="0 0 0"/>
    <geometry>
      <mesh filename="package://Rice_description/meshes/wheel_bl.stl" scale="0.001 0.001 0.001"/>
    </geometry>
  </collision>
</link>

<link name="${prefix}wheel_fl">
  <inertial>
    <origin xyz="0.002000000000003818 0.46499999999999997 4.429351555892799e-15" rpy="0 0 0"/>
    <mass value="65.80472593736363"/>
    <inertia ixx="1.584128" iyy="0.836383" izz="0.836383" ixy="0.0" iyz="-0.0" ixz="-0.0"/>
  </inertial>
  <visual>
    <origin xyz="0 0 0" rpy="0 0 0"/>
    <geometry>
      <mesh filename="package://Rice_description/meshes/wheel_fl.stl" scale="0.001 0.001 0.001"/>
    </geometry>
    <material name="Rice_silver"/>
  </visual>
  <collision>
    <origin xyz="0 0 0" rpy="0 0 0"/>
    <geometry>
      <mesh filename="package://Rice_description/meshes/wheel_fl.stl" scale="0.001 0.001 0.001"/>
    </geometry>
  </collision>
</link>

<joint name="${prefix}Revolute 9" type="continuous">
  <origin xyz="0.77 0.465 1.09" rpy="0.0 -0.0 0.0"/>
  <parent link="${prefix}base_link"/>
  <child link="${prefix}leg_br"/>
  <axis xyz="0.0 -1.0 0.0"/>
</joint>

<joint name="${prefix}Revolute 10" type="continuous">
  <origin xyz="0.0 0.465 1.09" rpy="0.0 -0.0 0.0"/>
  <parent link="${prefix}base_link"/>
  <child link="${prefix}leg_bl"/>
  <axis xyz="0.0 -1.0 0.0"/>
</joint>

<joint name="${prefix}Revolute 11" type="continuous">
  <origin xyz="0.77 0.465 0.0" rpy="0.0 -0.0 0.0"/>
  <parent link="${prefix}base_link"/>
  <child link="${prefix}leg_fr"/>
  <axis xyz="0.0 -1.0 0.0"/>
</joint>

<joint name="${prefix}Revolute 12" type="continuous">
  <origin xyz="0.0 0.465 -0.0" rpy="0.0 -0.0 0.0"/>
  <parent link="${prefix}base_link"/>
  <child link="${prefix}leg_fl"/>
  <axis xyz="0.0 -1.0 0.0"/>
</joint>

<joint name="${prefix}Revolute 13" type="continuous">
  <origin xyz="0.093 -0.67 0.0" rpy="0.0 -0.0 0.0"/>
  <parent link="${prefix}leg_br"/>
  <child link="${prefix}wheel_br"/>
  <axis xyz="1.0 0.0 0.0"/>
</joint>

<joint name="${prefix}Revolute 14" type="continuous">
  <origin xyz="0.093 -0.67 0.0" rpy="0.0 -0.0 0.0"/>
  <parent link="${prefix}leg_fr"/>
  <child link="${prefix}wheel_fr"/>
  <axis xyz="1.0 0.0 0.0"/>
</joint>

<joint name="${prefix}Revolute 15" type="continuous">
  <origin xyz="-0.093 -0.67 -0.0" rpy="0.0 -0.0 0.0"/>
  <parent link="${prefix}leg_bl"/>
  <child link="${prefix}wheel_bl"/>
  <axis xyz="-1.0 0.0 0.0"/>
</joint>

<joint name="${prefix}Revolute 16" type="continuous">
  <origin xyz="-0.093 -0.67 -0.0" rpy="0.0 -0.0 0.0"/>
  <parent link="${prefix}leg_fl"/>
  <child link="${prefix}wheel_fl"/>
  <axis xyz="-1.0 0.0 0.0"/>
</joint>

</xacro:macro>
</robot>
