<?xml version="1.0" ?>
<robot name="Rice" xmlns:xacro="http://www.ros.org/wiki/xacro">

<xacro:include filename="$(find Rice_description)/urdf/materials.xacro" />
<xacro:include filename="$(find Rice_description)/urdf/Rice.ros2control" />
<xacro:include filename="$(find Rice_description)/urdf/Rice.gazebo" />
<link name="base_link">
  <inertial>
    <origin xyz="0.38402832945911597 0.567977724226758 0.9197289790734344" rpy="0 0 0"/>
    <mass value="111.52248073403698"/>
    <inertia ixx="19.278738" iyy="11.892444" izz="29.802061" ixy="0.058745" iyz="0.077376" ixz="0.004947"/>
  </inertial>
  <visual>
    <origin xyz="0 0 0" rpy="0 0 0"/>
    <geometry>
      <mesh filename="file://$(find Rice_description)/meshes/base_link.stl" scale="0.001 0.001 0.001"/>
    </geometry>
    <material name="silver"/>
  </visual>
  <collision>
    <origin xyz="0 0 0" rpy="0 0 0"/>
    <geometry>
      <mesh filename="file://$(find Rice_description)/meshes/base_link.stl" scale="0.001 0.001 0.001"/>
    </geometry>
  </collision>
</link>

<link name="leg_br_1">
  <inertial>
    <origin xyz="0.02067495895251792 0.05948901031816567 -0.42960523779205095" rpy="0 0 0"/>
    <mass value="19.428196282242897"/>
    <inertia ixx="0.69198" iyy="0.64895" izz="0.118365" ixy="-0.016967" iyz="-0.04479" ixz="-0.001759"/>
  </inertial>
  <visual>
    <origin xyz="-0.77 -0.025965 -0.876501" rpy="0 0 0"/>
    <geometry>
      <mesh filename="file://$(find Rice_description)/meshes/leg_br_1.stl" scale="0.001 0.001 0.001"/>
    </geometry>
    <material name="silver"/>
  </visual>
  <collision>
    <origin xyz="-0.77 -0.025965 -0.876501" rpy="0 0 0"/>
    <geometry>
      <mesh filename="file://$(find Rice_description)/meshes/leg_br_1.stl" scale="0.001 0.001 0.001"/>
    </geometry>
  </collision>
</link>

<link name="leg_bl_1">
  <inertial>
    <origin xyz="-0.020209424216131984 0.05818392702927147 -0.4348056527161479" rpy="0 0 0"/>
    <mass value="19.9033372562808"/>
    <inertia ixx="0.720932" iyy="0.676639" izz="0.120784" ixy="0.017565" iyz="-0.050773" ixz="0.003917"/>
  </inertial>
  <visual>
    <origin xyz="-0.0 -0.025965 -0.876501" rpy="0 0 0"/>
    <geometry>
      <mesh filename="file://$(find Rice_description)/meshes/leg_bl_1.stl" scale="0.001 0.001 0.001"/>
    </geometry>
    <material name="silver"/>
  </visual>
  <collision>
    <origin xyz="-0.0 -0.025965 -0.876501" rpy="0 0 0"/>
    <geometry>
      <mesh filename="file://$(find Rice_description)/meshes/leg_bl_1.stl" scale="0.001 0.001 0.001"/>
    </geometry>
  </collision>
</link>

<link name="leg_fr_1">
  <inertial>
    <origin xyz="0.020209424438183965 -0.058184301381010606 -0.43480565196065807" rpy="0 0 0"/>
    <mass value="19.90333719348541"/>
    <inertia ixx="0.720932" iyy="0.676639" izz="0.120784" ixy="0.017565" iyz="0.050773" ixz="-0.003917"/>
  </inertial>
  <visual>
    <origin xyz="-0.77 -1.115965 -0.876501" rpy="0 0 0"/>
    <geometry>
      <mesh filename="file://$(find Rice_description)/meshes/leg_fr_1.stl" scale="0.001 0.001 0.001"/>
    </geometry>
    <material name="silver"/>
  </visual>
  <collision>
    <origin xyz="-0.77 -1.115965 -0.876501" rpy="0 0 0"/>
    <geometry>
      <mesh filename="file://$(find Rice_description)/meshes/leg_fr_1.stl" scale="0.001 0.001 0.001"/>
    </geometry>
  </collision>
</link>

<link name="leg_fl_1">
  <inertial>
    <origin xyz="-0.020233756052453953 -0.058202816166196714 -0.4347330181911013" rpy="0 0 0"/>
    <mass value="19.897003188386865"/>
    <inertia ixx="0.72058" iyy="0.676271" izz="0.120724" ixy="-0.017537" iyz="0.050689" ixz="0.003807"/>
  </inertial>
  <visual>
    <origin xyz="-0.0 -1.115965 -0.876501" rpy="0 0 0"/>
    <geometry>
      <mesh filename="file://$(find Rice_description)/meshes/leg_fl_1.stl" scale="0.001 0.001 0.001"/>
    </geometry>
    <material name="silver"/>
  </visual>
  <collision>
    <origin xyz="-0.0 -1.115965 -0.876501" rpy="0 0 0"/>
    <geometry>
      <mesh filename="file://$(find Rice_description)/meshes/leg_fl_1.stl" scale="0.001 0.001 0.001"/>
    </geometry>
  </collision>
</link>

<link name="wheel_br_1">
  <inertial>
    <origin xyz="-0.0036583592134993292 -1.8708468446995696e-07 4.2335822600381157e-07" rpy="0 0 0"/>
    <mass value="65.80472593736363"/>
    <inertia ixx="1.584128" iyy="0.836383" izz="0.836383" ixy="0.0" iyz="0.0" ixz="-0.0"/>
  </inertial>
  <visual>
    <origin xyz="-0.863 -0.025965 -0.206501" rpy="0 0 0"/>
    <geometry>
      <mesh filename="file://$(find Rice_description)/meshes/wheel_br_1.stl" scale="0.001 0.001 0.001"/>
    </geometry>
    <material name="silver"/>
  </visual>
  <collision>
    <origin xyz="-0.863 -0.025965 -0.206501" rpy="0 0 0"/>
    <geometry>
      <mesh filename="file://$(find Rice_description)/meshes/wheel_br_1.stl" scale="0.001 0.001 0.001"/>
    </geometry>
  </collision>
</link>

<link name="wheel_fr_1">
  <inertial>
    <origin xyz="-0.0036583592134961096 -1.8708470195250015e-07 4.233582252821666e-07" rpy="0 0 0"/>
    <mass value="65.80472593736363"/>
    <inertia ixx="1.584128" iyy="0.836383" izz="0.836383" ixy="-0.0" iyz="0.0" ixz="0.0"/>
  </inertial>
  <visual>
    <origin xyz="-0.863 -1.115965 -0.206501" rpy="0 0 0"/>
    <geometry>
      <mesh filename="file://$(find Rice_description)/meshes/wheel_fr_1.stl" scale="0.001 0.001 0.001"/>
    </geometry>
    <material name="silver"/>
  </visual>
  <collision>
    <origin xyz="-0.863 -1.115965 -0.206501" rpy="0 0 0"/>
    <geometry>
      <mesh filename="file://$(find Rice_description)/meshes/wheel_fr_1.stl" scale="0.001 0.001 0.001"/>
    </geometry>
  </collision>
</link>

<link name="wheel_bl_1">
  <inertial>
    <origin xyz="0.0020000000000000573 -1.870846836303508e-07 4.233582258372781e-07" rpy="0 0 0"/>
    <mass value="65.80472593736363"/>
    <inertia ixx="1.584128" iyy="0.836383" izz="0.836383" ixy="-0.0" iyz="0.0" ixz="0.0"/>
  </inertial>
  <visual>
    <origin xyz="0.093 -0.025965 -0.206501" rpy="0 0 0"/>
    <geometry>
      <mesh filename="file://$(find Rice_description)/meshes/wheel_bl_1.stl" scale="0.001 0.001 0.001"/>
    </geometry>
    <material name="silver"/>
  </visual>
  <collision>
    <origin xyz="0.093 -0.025965 -0.206501" rpy="0 0 0"/>
    <geometry>
      <mesh filename="file://$(find Rice_description)/meshes/wheel_bl_1.stl" scale="0.001 0.001 0.001"/>
    </geometry>
  </collision>
</link>

<link name="wheel_fl_1">
  <inertial>
    <origin xyz="0.0020000000000037488 -1.8708469617934043e-07 4.2335822519889987e-07" rpy="0 0 0"/>
    <mass value="65.80472593736363"/>
    <inertia ixx="1.584128" iyy="0.836383" izz="0.836383" ixy="0.0" iyz="0.0" ixz="0.0"/>
  </inertial>
  <visual>
    <origin xyz="0.093 -1.115965 -0.206501" rpy="0 0 0"/>
    <geometry>
      <mesh filename="file://$(find Rice_description)/meshes/wheel_fl_1.stl" scale="0.001 0.001 0.001"/>
    </geometry>
    <material name="silver"/>
  </visual>
  <collision>
    <origin xyz="0.093 -1.115965 -0.206501" rpy="0 0 0"/>
    <geometry>
      <mesh filename="file://$(find Rice_description)/meshes/wheel_fl_1.stl" scale="0.001 0.001 0.001"/>
    </geometry>
  </collision>
</link>

<joint name="Revolute 9" type="continuous">
  <origin xyz="0.77 0.025965 0.876501" rpy="0 0 0"/>
  <parent link="base_link"/>
  <child link="leg_br_1"/>
  <axis xyz="-0.0 -0.0 -1.0"/>
</joint>

<joint name="Revolute 10" type="continuous">
  <origin xyz="0.0 0.025965 0.876501" rpy="0 0 0"/>
  <parent link="base_link"/>
  <child link="leg_bl_1"/>
  <axis xyz="-0.0 -0.0 -1.0"/>
</joint>

<joint name="Revolute 11" type="continuous">
  <origin xyz="0.77 1.115965 0.876501" rpy="0 0 0"/>
  <parent link="base_link"/>
  <child link="leg_fr_1"/>
  <axis xyz="-0.0 -0.0 -1.0"/>
</joint>

<joint name="Revolute 12" type="continuous">
  <origin xyz="0.0 1.115965 0.876501" rpy="0 0 0"/>
  <parent link="base_link"/>
  <child link="leg_fl_1"/>
  <axis xyz="-0.0 -0.0 -1.0"/>
</joint>

<joint name="Revolute 13" type="continuous">
  <origin xyz="0.093 0.0 -0.67" rpy="0 0 0"/>
  <parent link="leg_br_1"/>
  <child link="wheel_br_1"/>
  <axis xyz="1.0 -0.0 -0.0"/>
</joint>

<joint name="Revolute 14" type="continuous">
  <origin xyz="0.093 0.0 -0.67" rpy="0 0 0"/>
  <parent link="leg_fr_1"/>
  <child link="wheel_fr_1"/>
  <axis xyz="1.0 0.0 -0.0"/>
</joint>

<joint name="Revolute 15" type="continuous">
  <origin xyz="-0.093 0.0 -0.67" rpy="0 0 0"/>
  <parent link="leg_bl_1"/>
  <child link="wheel_bl_1"/>
  <axis xyz="-1.0 -0.0 0.0"/>
</joint>

<joint name="Revolute 16" type="continuous">
  <origin xyz="-0.093 0.0 -0.67" rpy="0 0 0"/>
  <parent link="leg_fl_1"/>
  <child link="wheel_fl_1"/>
  <axis xyz="-1.0 -0.0 0.0"/>
</joint>

</robot>
