<?xml version="1.0" ?>
<robot name="Rice" xmlns:xacro="http://www.ros.org/wiki/xacro">

<xacro:include filename="$(find Rice_description)/urdf/materials.xacro" />
<xacro:include filename="$(find Rice_description)/urdf/Rice.ros2control" />
<xacro:include filename="$(find Rice_description)/urdf/Rice.gazebo" />
<link name="base_link">
  <inertial>
    <origin xyz="0.38402832945911597 0.5679777242267577 0.9197289790734346" rpy="0 0 0"/>
    <mass value="111.52248073403698"/>
    <inertia ixx="19.278738" iyy="11.892444" izz="29.802061" ixy="0.058745" iyz="0.077376" ixz="0.004947"/>
  </inertial>
  <visual>
    <origin xyz="0 0 0" rpy="0 0 0"/>
    <geometry>
      <mesh filename="file://$(find Rice_description)/meshes/base_link.stl" scale="0.001 0.001 0.001"/>
    </geometry>
    <material name="silver"/>
  </visual>
  <collision>
    <origin xyz="0 0 0" rpy="0 0 0"/>
    <geometry>
      <mesh filename="file://$(find Rice_description)/meshes/base_link.stl" scale="0.001 0.001 0.001"/>
    </geometry>
  </collision>
</link>

<link name="leg_br_1">
  <inertial>
    <origin xyz="0.02067495895251803 0.05948901031816539 -0.4296052377920505" rpy="0 0 0"/>
    <mass value="19.428196282242897"/>
    <inertia ixx="0.69198" iyy="0.64895" izz="0.118365" ixy="-0.016967" iyz="-0.04479" ixz="-0.001759"/>
  </inertial>
  <visual>
    <origin xyz="-0.77 -0.025965 -0.876501" rpy="0 0 0"/>
    <geometry>
      <mesh filename="file://$(find Rice_description)/meshes/leg_br_1.stl" scale="0.001 0.001 0.001"/>
    </geometry>
    <material name="silver"/>
  </visual>
  <collision>
    <origin xyz="-0.77 -0.025965 -0.876501" rpy="0 0 0"/>
    <geometry>
      <mesh filename="file://$(find Rice_description)/meshes/leg_br_1.stl" scale="0.001 0.001 0.001"/>
    </geometry>
  </collision>
</link>

<link name="leg_bl_1">
  <inertial>
    <origin xyz="-0.020209424216131908 0.05818392702927119 -0.43480565271614746" rpy="0 0 0"/>
    <mass value="19.9033372562808"/>
    <inertia ixx="0.720932" iyy="0.676639" izz="0.120784" ixy="0.017565" iyz="-0.050773" ixz="0.003917"/>
  </inertial>
  <visual>
    <origin xyz="-0.0 -0.025965 -0.876501" rpy="0 0 0"/>
    <geometry>
      <mesh filename="file://$(find Rice_description)/meshes/leg_bl_1.stl" scale="0.001 0.001 0.001"/>
    </geometry>
    <material name="silver"/>
  </visual>
  <collision>
    <origin xyz="-0.0 -0.025965 -0.876501" rpy="0 0 0"/>
    <geometry>
      <mesh filename="file://$(find Rice_description)/meshes/leg_bl_1.stl" scale="0.001 0.001 0.001"/>
    </geometry>
  </collision>
</link>

<link name="leg_fr_1">
  <inertial>
    <origin xyz="0.020209424438183965 -0.058184301381010606 -0.4348056519606576" rpy="0 0 0"/>
    <mass value="19.90333719348541"/>
    <inertia ixx="0.720932" iyy="0.676639" izz="0.120784" ixy="0.017565" iyz="0.050773" ixz="-0.003917"/>
  </inertial>
  <visual>
    <origin xyz="-0.77 -1.115965 -0.876501" rpy="0 0 0"/>
    <geometry>
      <mesh filename="file://$(find Rice_description)/meshes/leg_fr_1.stl" scale="0.001 0.001 0.001"/>
    </geometry>
    <material name="silver"/>
  </visual>
  <collision>
    <origin xyz="-0.77 -1.115965 -0.876501" rpy="0 0 0"/>
    <geometry>
      <mesh filename="file://$(find Rice_description)/meshes/leg_fr_1.stl" scale="0.001 0.001 0.001"/>
    </geometry>
  </collision>
</link>

<link name="leg_fl_1">
  <inertial>
    <origin xyz="-0.02023375605245399 -0.058202816166196936 -0.4347330181911009" rpy="0 0 0"/>
    <mass value="19.897003188386865"/>
    <inertia ixx="0.72058" iyy="0.676271" izz="0.120724" ixy="-0.017537" iyz="0.050689" ixz="0.003807"/>
  </inertial>
  <visual>
    <origin xyz="0.0 -1.115965 -0.876501" rpy="0 0 0"/>
    <geometry>
      <mesh filename="file://$(find Rice_description)/meshes/leg_fl_1.stl" scale="0.001 0.001 0.001"/>
    </geometry>
    <material name="silver"/>
  </visual>
  <collision>
    <origin xyz="0.0 -1.115965 -0.876501" rpy="0 0 0"/>
    <geometry>
      <mesh filename="file://$(find Rice_description)/meshes/leg_fl_1.stl" scale="0.001 0.001 0.001"/>
    </geometry>
  </collision>
</link>

<link name="wheel_br_1">
  <inertial>
    <origin xyz="-0.0036583592134993292 -1.8708468475445161e-07 4.2335822636463405e-07" rpy="0 0 0"/>
    <mass value="65.80472593736363"/>
    <inertia ixx="1.584128" iyy="0.836383" izz="0.836383" ixy="0.0" iyz="-0.0" ixz="-0.0"/>
  </inertial>
  <visual>
    <origin xyz="-0.863 -0.025965 -0.206501" rpy="0 0 0"/>
    <geometry>
      <mesh filename="file://$(find Rice_description)/meshes/wheel_br_1.stl" scale="0.001 0.001 0.001"/>
    </geometry>
    <material name="silver"/>
  </visual>
  <collision>
    <origin xyz="-0.863 -0.025965 -0.206501" rpy="0 0 0"/>
    <geometry>
      <mesh filename="file://$(find Rice_description)/meshes/wheel_br_1.stl" scale="0.001 0.001 0.001"/>
    </geometry>
  </collision>
</link>

<link name="wheel_fr_1">
  <inertial>
    <origin xyz="-0.0036583592134963316 -1.8708470239658936e-07 4.233582256152335e-07" rpy="0 0 0"/>
    <mass value="65.80472593736363"/>
    <inertia ixx="1.584128" iyy="0.836383" izz="0.836383" ixy="-0.0" iyz="-0.0" ixz="-0.0"/>
  </inertial>
  <visual>
    <origin xyz="-0.863 -1.115965 -0.206501" rpy="0 0 0"/>
    <geometry>
      <mesh filename="file://$(find Rice_description)/meshes/wheel_fr_1.stl" scale="0.001 0.001 0.001"/>
    </geometry>
    <material name="silver"/>
  </visual>
  <collision>
    <origin xyz="-0.863 -1.115965 -0.206501" rpy="0 0 0"/>
    <geometry>
      <mesh filename="file://$(find Rice_description)/meshes/wheel_fr_1.stl" scale="0.001 0.001 0.001"/>
    </geometry>
  </collision>
</link>

<link name="wheel_bl_1">
  <inertial>
    <origin xyz="0.0020000000000001406 -1.8708468407444e-07 4.233582261981006e-07" rpy="0 0 0"/>
    <mass value="65.80472593736363"/>
    <inertia ixx="1.584128" iyy="0.836383" izz="0.836383" ixy="-0.0" iyz="0.0" ixz="0.0"/>
  </inertial>
  <visual>
    <origin xyz="0.093 -0.025965 -0.206501" rpy="0 0 0"/>
    <geometry>
      <mesh filename="file://$(find Rice_description)/meshes/wheel_bl_1.stl" scale="0.001 0.001 0.001"/>
    </geometry>
    <material name="silver"/>
  </visual>
  <collision>
    <origin xyz="0.093 -0.025965 -0.206501" rpy="0 0 0"/>
    <geometry>
      <mesh filename="file://$(find Rice_description)/meshes/wheel_bl_1.stl" scale="0.001 0.001 0.001"/>
    </geometry>
  </collision>
</link>

<link name="wheel_fl_1">
  <inertial>
    <origin xyz="0.0020000000000036933 -1.8708469684547424e-07 4.2335822555972236e-07" rpy="0 0 0"/>
    <mass value="65.80472593736363"/>
    <inertia ixx="1.584128" iyy="0.836383" izz="0.836383" ixy="0.0" iyz="0.0" ixz="0.0"/>
  </inertial>
  <visual>
    <origin xyz="0.093 -1.115965 -0.206501" rpy="0 0 0"/>
    <geometry>
      <mesh filename="file://$(find Rice_description)/meshes/wheel_fl_1.stl" scale="0.001 0.001 0.001"/>
    </geometry>
    <material name="silver"/>
  </visual>
  <collision>
    <origin xyz="0.093 -1.115965 -0.206501" rpy="0 0 0"/>
    <geometry>
      <mesh filename="file://$(find Rice_description)/meshes/wheel_fl_1.stl" scale="0.001 0.001 0.001"/>
    </geometry>
  </collision>
</link>

<link name="arm_1">
  <inertial>
    <origin xyz="-0.2584017090179747 0.002110884278794578 -0.07218880073119238" rpy="0 0 0"/>
    <mass value="22.741450985256424"/>
    <inertia ixx="1.72933" iyy="1.730341" izz="3.147968" ixy="0.000336" iyz="0.000291" ixz="-0.001081"/>
  </inertial>
  <visual>
    <origin xyz="-0.6435 -0.570965 -0.873501" rpy="0 0 0"/>
    <geometry>
      <mesh filename="file://$(find Rice_description)/meshes/arm_1.stl" scale="0.001 0.001 0.001"/>
    </geometry>
    <material name="silver"/>
  </visual>
  <collision>
    <origin xyz="-0.6435 -0.570965 -0.873501" rpy="0 0 0"/>
    <geometry>
      <mesh filename="file://$(find Rice_description)/meshes/arm_1.stl" scale="0.001 0.001 0.001"/>
    </geometry>
  </collision>
</link>

<link name="solar_1">
  <inertial>
    <origin xyz="4.377609386096992e-13 0.39349657074105626 0.24368297346942225" rpy="0 0 0"/>
    <mass value="131.93512225473023"/>
    <inertia ixx="26.841833" iyy="21.913769" izz="48.508633" ixy="-0.0" iyz="-6.5e-05" ixz="0.0"/>
  </inertial>
  <visual>
    <origin xyz="-0.385 -0.177463 -0.982466" rpy="0 0 0"/>
    <geometry>
      <mesh filename="file://$(find Rice_description)/meshes/solar_1.stl" scale="0.001 0.001 0.001"/>
    </geometry>
    <material name="silver"/>
  </visual>
  <collision>
    <origin xyz="-0.385 -0.177463 -0.982466" rpy="0 0 0"/>
    <geometry>
      <mesh filename="file://$(find Rice_description)/meshes/solar_1.stl" scale="0.001 0.001 0.001"/>
    </geometry>
  </collision>
</link>

<joint name="Revolute 9" type="continuous">
  <origin xyz="0.77 0.025965 0.876501" rpy="0 0 0"/>
  <parent link="base_link"/>
  <child link="leg_br_1"/>
  <axis xyz="-0.0 -0.0 -1.0"/>
</joint>

<joint name="Revolute 10" type="continuous">
  <origin xyz="0.0 0.025965 0.876501" rpy="0 0 0"/>
  <parent link="base_link"/>
  <child link="leg_bl_1"/>
  <axis xyz="-0.0 -0.0 -1.0"/>
</joint>

<joint name="Revolute 11" type="continuous">
  <origin xyz="0.77 1.115965 0.876501" rpy="0 0 0"/>
  <parent link="base_link"/>
  <child link="leg_fr_1"/>
  <axis xyz="-0.0 -0.0 -1.0"/>
</joint>

<joint name="Revolute 12" type="continuous">
  <origin xyz="0.0 1.115965 0.876501" rpy="0 0 0"/>
  <parent link="base_link"/>
  <child link="leg_fl_1"/>
  <axis xyz="-0.0 -0.0 -1.0"/>
</joint>

<joint name="Revolute 13" type="continuous">
  <origin xyz="0.093 0.0 -0.67" rpy="0 0 0"/>
  <parent link="leg_br_1"/>
  <child link="wheel_br_1"/>
  <axis xyz="1.0 0.0 -0.0"/>
</joint>

<joint name="Revolute 14" type="continuous">
  <origin xyz="0.093 0.0 -0.67" rpy="0 0 0"/>
  <parent link="leg_fr_1"/>
  <child link="wheel_fr_1"/>
  <axis xyz="1.0 0.0 -0.0"/>
</joint>

<joint name="Revolute 15" type="continuous">
  <origin xyz="-0.093 0.0 -0.67" rpy="0 0 0"/>
  <parent link="leg_bl_1"/>
  <child link="wheel_bl_1"/>
  <axis xyz="-1.0 -0.0 0.0"/>
</joint>

<joint name="Revolute 16" type="continuous">
  <origin xyz="-0.093 0.0 -0.67" rpy="0 0 0"/>
  <parent link="leg_fl_1"/>
  <child link="wheel_fl_1"/>
  <axis xyz="-1.0 -0.0 0.0"/>
</joint>

<joint name="Rigid 17" type="fixed">
  <origin xyz="0.6435 0.570965 0.873501" rpy="0 0 0"/>
  <parent link="base_link"/>
  <child link="arm_1"/>
</joint>

<joint name="Rigid 18" type="fixed">
  <origin xyz="0.385 0.177463 0.982466" rpy="0 0 0"/>
  <parent link="base_link"/>
  <child link="solar_1"/>
</joint>

</robot>
